Workbook

Sheet Audit Report
A1: Bazaarvoice Product Catalog Audit Report
A2: All regional instances | All-time catalog snapshot | Run date in source: 2026-08-12 UTC
A3: Documentation: https://pgone.sharepoint.com/:p:/s/GlobalProductServices/IQAhg8ackh-HQ77DjbpXzz43ASkqCZKDUUbpZ9z4fYTL8-M?e=ELbrVw
A5: TOP PRIORITY ALERT
A6: Most Critical Issue | B6: Reviews are currently hidden because they are associated with inactive products.
A7: Total Impact | B7: =SUMIF('pampers-en_us'!D8:D129,"Inactive",'pampers-en_us'!M8:M129)+SUMIF('pampers-es'!D8:D38,"Inactive",'pampers-es'!M8:M38)+SUMIF('pampers-en_gb'!D8:D45,"Inactive",'pampers-en_gb'!M8:M45)+SUMIF('pampers-de_de'!D8:D43,"Inactive",'pampers-de_de'!M8:M43)+SUMIF('pampers-fr_fr'!D8:D86,"Inactive",'pampers-fr_fr'!M8:M86)+SUMIF(pgdodotspain!D8:D36,"Inactive",pgdodotspain!M8:M36)+SUMIF('pampers-ja_jp'!D8:D40,"Inactive",'pampers-ja_jp'!M8:M40) -> 62301
A8: Number of Affected Products | B8: =COUNTIFS('pampers-en_us'!D8:D129,"Inactive",'pampers-en_us'!M8:M129,">0")+COUNTIFS('pampers-es'!D8:D38,"Inactive",'pampers-es'!M8:M38,">0")+COUNTIFS('pampers-en_gb'!D8:D45,"Inactive",'pampers-en_gb'!M8:M45,">0")+COUNTIFS('pampers-de_de'!D8:D43,"Inactive",'pampers-de_de'!M8:M43,">0")+COUNTIFS('pampers-fr_fr'!D8:D86,"Inactive",'pampers-fr_fr'!M8:M86,">0")+COUNTIFS(pgdodotspain!D8:D36,"Inactive",pgdodotspain!M8:M36,">0")+COUNTIFS('pampers-ja_jp'!D8:D40,"Inactive",'pampers-ja_jp'!M8:M40,">0") -> 229
A9: Number of Reviews Hidden/Tagged to Inactive Products | B9: =SUMIF('pampers-en_us'!D8:D129,"Inactive",'pampers-en_us'!M8:M129)+SUMIF('pampers-es'!D8:D38,"Inactive",'pampers-es'!M8:M38)+SUMIF('pampers-en_gb'!D8:D45,"Inactive",'pampers-en_gb'!M8:M45)+SUMIF('pampers-de_de'!D8:D43,"Inactive",'pampers-de_de'!M8:M43)+SUMIF('pampers-fr_fr'!D8:D86,"Inactive",'pampers-fr_fr'!M8:M86)+SUMIF(pgdodotspain!D8:D36,"Inactive",pgdodotspain!M8:M36)+SUMIF('pampers-ja_jp'!D8:D40,"Inactive",'pampers-ja_jp'!M8:M40) -> 62301
A10: % Reviews Hidden/Tagged to Inactive Products | B10: =IFERROR(B9/(SUM('pampers-en_us'!M8:M129)+SUM('pampers-es'!M8:M38)+SUM('pampers-en_gb'!M8:M45)+SUM('pampers-de_de'!M8:M43)+SUM('pampers-fr_fr'!M8:M86)+SUM(pgdodotspain!M8:M36)+SUM('pampers-ja_jp'!M8:M40)),0) -> 0.25959399
A11: Required Action Summary | B11: Prioritize reviewed inactive products.
A12: Recommended Fix | B12: Map IDs to live PDPs; then activate.
A13: Suggestion Impact Level | B13: CRUCIAL
A15: SECTION 1: CRITICAL FIELD DEFINITIONS FOR AUDIT
A16: Critical Field | B16: Column Reference | C16: Why Critical | D16: Business Impact if Missing | E16: Recommended Action | F16: Documentation Reference
A17: Product ID | B17: C | C17: Primary catalog matching key. | D17: Matching and governance fail. | E17: Use one stable canonical ID. | F17: https://pgone.sharepoint.com/:p:/s/GlobalProductServices/IQAhg8ackh-HQ77DjbpXzz43ASkqCZKDUUbpZ9z4fYTL8-M?e=ELbrVw
A18: UPC/EAN | B18: I / J | C18: Regional syndication identifier. | D18: Syndication can be blocked. | E18: Populate UPC in NA; EAN elsewhere. | F18: https://pgone.sharepoint.com/:p:/s/GlobalProductServices/IQAhg8ackh-HQ77DjbpXzz43ASkqCZKDUUbpZ9z4fYTL8-M?e=ELbrVw
A19: Product Name | B19: E | C19: Customer-facing product identity. | D19: PDP clarity is reduced. | E19: Supply the approved local name. | F19: https://pgone.sharepoint.com/:p:/s/GlobalProductServices/IQAhg8ackh-HQ77DjbpXzz43ASkqCZKDUUbpZ9z4fYTL8-M?e=ELbrVw
A20: Product Description | B20: F | C20: Core product content. | D20: PDP completeness is reduced. | E20: Supply approved local copy. | F20: https://pgone.sharepoint.com/:p:/s/GlobalProductServices/IQAhg8ackh-HQ77DjbpXzz43ASkqCZKDUUbpZ9z4fYTL8-M?e=ELbrVw
A21: Product Page URL / PDP URL | B21: G | C21: Links reviews to the live PDP. | D21: Reviews may not render on PDP. | E21: Use the canonical live PDP URL. | F21: https://pgone.sharepoint.com/:p:/s/GlobalProductServices/IQAhg8ackh-HQ77DjbpXzz43ASkqCZKDUUbpZ9z4fYTL8-M?e=ELbrVw
A22: Image URL | B22: H | C22: Provides product imagery. | D22: Catalog presentation is weakened. | E22: Use a reachable canonical image. | F22: https://pgone.sharepoint.com/:p:/s/GlobalProductServices/IQAhg8ackh-HQ77DjbpXzz43ASkqCZKDUUbpZ9z4fYTL8-M?e=ELbrVw
A23: Brand | B23: B | C23: Supports attribution and reporting. | D23: Brand reporting can fragment. | E23: Use approved brand taxonomy. | F23: https://pgone.sharepoint.com/:p:/s/GlobalProductServices/IQAhg8ackh-HQ77DjbpXzz43ASkqCZKDUUbpZ9z4fYTL8-M?e=ELbrVw
A24: Product Status | B24: D | C24: Controls product visibility. | D24: Inactive items hide reviews. | E24: Validate Active/Inactive status. | F24: https://pgone.sharepoint.com/:p:/s/GlobalProductServices/IQAhg8ackh-HQ77DjbpXzz43ASkqCZKDUUbpZ9z4fYTL8-M?e=ELbrVw
A26: SECTION 2: VOLUME-BASED SUMMARY BY INSTANCE
A27: Instance / Region | B27: Total Products | C27: Active Products | D27: Inactive Products | E27: % Inactive | F27: Total Reviews | G27: Reviews Hidden/Tagged to Inactive Product | H27: % Reviews Hidden/Tagged to Inactive Product | I27: Missing UPC/EAN | J27: Missing Description | K27: Missing Image URL | L27: Business Impact | M27: Recommended Action | N27: Suggestion Impact
A28: United States (EN) | B28: =COUNTIF('pampers-en_us'!D8:D129,"<>") -> 122 | C28: =COUNTIF('pampers-en_us'!D8:D129,"Active") -> 20 | D28: =COUNTIF('pampers-en_us'!D8:D129,"Inactive") -> 102 | E28: =IFERROR(D28/B28,0) -> 0.83606557 | F28: =SUM('pampers-en_us'!M8:M129) -> 154472 | G28: =SUMIF('pampers-en_us'!D8:D129,"Inactive",'pampers-en_us'!M8:M129) -> 34000 | H28: =IFERROR(G28/F28,0) -> 0.22010461 | I28: {=SUMPRODUCT(--('pampers-en_us'!D8:D129<>""),--(LEN(TRIM('pampers-en_us'!I8:I129))=0))} -> 36 | J28: {=SUMPRODUCT(--('pampers-en_us'!D8:D129<>""),--(LEN(TRIM('pampers-en_us'!F8:F129))=0))} -> 38 | K28: {=SUMPRODUCT(--('pampers-en_us'!D8:D129<>""),--(LEN(TRIM('pampers-en_us'!H8:H129))=0))} -> 36 | L28: =IF(G28>0,"Hidden reviews reduce social proof.","No hidden-review impact found.") -> Hidden reviews reduce social proof. | M28: =IF(G28>0,"Map reviewed IDs; then activate.","Maintain status governance.") -> Map reviewed IDs; then activate. | N28: =IF(G28>0,"CRUCIAL",IF(I28>0,"HIGH",IF(J28+K28>0,"MEDIUM","LOW"))) -> CRUCIAL
A29: United States (ES) | B29: =COUNTIF('pampers-es'!D8:D38,"<>") -> 31 | C29: =COUNTIF('pampers-es'!D8:D38,"Active") -> 0 | D29: =COUNTIF('pampers-es'!D8:D38,"Inactive") -> 31 | E29: =IFERROR(D29/B29,0) -> 1 | F29: =SUM('pampers-es'!M8:M38) -> 1884 | G29: =SUMIF('pampers-es'!D8:D38,"Inactive",'pampers-es'!M8:M38) -> 1884 | H29: =IFERROR(G29/F29,0) -> 1 | I29: {=SUMPRODUCT(--('pampers-es'!D8:D38<>""),--(LEN(TRIM('pampers-es'!I8:I38))=0))} -> 3 | J29: {=SUMPRODUCT(--('pampers-es'!D8:D38<>""),--(LEN(TRIM('pampers-es'!F8:F38))=0))} -> 3 | K29: {=SUMPRODUCT(--('pampers-es'!D8:D38<>""),--(LEN(TRIM('pampers-es'!H8:H38))=0))} -> 2 | L29: =IF(G29>0,"Hidden reviews reduce social proof.","No hidden-review impact found.") -> Hidden reviews reduce social proof. | M29: =IF(G29>0,"Map reviewed IDs; then activate.","Maintain status governance.") -> Map reviewed IDs; then activate. | N29: =IF(G29>0,"CRUCIAL",IF(I29>0,"HIGH",IF(J29+K29>0,"MEDIUM","LOW"))) -> CRUCIAL
A30: United Kingdom | B30: =COUNTIF('pampers-en_gb'!D8:D45,"<>") -> 38 | C30: =COUNTIF('pampers-en_gb'!D8:D45,"Active") -> 15 | D30: =COUNTIF('pampers-en_gb'!D8:D45,"Inactive") -> 23 | E30: =IFERROR(D30/B30,0) -> 0.60526316 | F30: =SUM('pampers-en_gb'!M8:M45) -> 13143 | G30: =SUMIF('pampers-en_gb'!D8:D45,"Inactive",'pampers-en_gb'!M8:M45) -> 1580 | H30: =IFERROR(G30/F30,0) -> 0.12021608 | I30: {=SUMPRODUCT(--('pampers-en_gb'!D8:D45<>""),--(LEN(TRIM('pampers-en_gb'!J8:J45))=0))} -> 7 | J30: {=SUMPRODUCT(--('pampers-en_gb'!D8:D45<>""),--(LEN(TRIM('pampers-en_gb'!F8:F45))=0))} -> 5 | K30: {=SUMPRODUCT(--('pampers-en_gb'!D8:D45<>""),--(LEN(TRIM('pampers-en_gb'!H8:H45))=0))} -> 7 | L30: =IF(G30>0,"Hidden reviews reduce social proof.","No hidden-review impact found.") -> Hidden reviews reduce social proof. | M30: =IF(G30>0,"Map reviewed IDs; then activate.","Maintain status governance.") -> Map reviewed IDs; then activate. | N30: =IF(G30>0,"CRUCIAL",IF(I30>0,"HIGH",IF(J30+K30>0,"MEDIUM","LOW"))) -> CRUCIAL
A31: Germany | B31: =COUNTIF('pampers-de_de'!D8:D43,"<>") -> 36 | C31: =COUNTIF('pampers-de_de'!D8:D43,"Active") -> 11 | D31: =COUNTIF('pampers-de_de'!D8:D43,"Inactive") -> 25 | E31: =IFERROR(D31/B31,0) -> 0.69444444 | F31: =SUM('pampers-de_de'!M8:M43) -> 30459 | G31: =SUMIF('pampers-de_de'!D8:D43,"Inactive",'pampers-de_de'!M8:M43) -> 9214 | H31: =IFERROR(G31/F31,0) -> 0.30250501 | I31: {=SUMPRODUCT(--('pampers-de_de'!D8:D43<>""),--(LEN(TRIM('pampers-de_de'!J8:J43))=0))} -> 9 | J31: {=SUMPRODUCT(--('pampers-de_de'!D8:D43<>""),--(LEN(TRIM('pampers-de_de'!F8:F43))=0))} -> 6 | K31: {=SUMPRODUCT(--('pampers-de_de'!D8:D43<>""),--(LEN(TRIM('pampers-de_de'!H8:H43))=0))} -> 11 | L31: =IF(G31>0,"Hidden reviews reduce social proof.","No hidden-review impact found.") -> Hidden reviews reduce social proof. | M31: =IF(G31>0,"Map reviewed IDs; then activate.","Maintain status governance.") -> Map reviewed IDs; then activate. | N31: =IF(G31>0,"CRUCIAL",IF(I31>0,"HIGH",IF(J31+K31>0,"MEDIUM","LOW"))) -> CRUCIAL
A32: France | B32: =COUNTIF('pampers-fr_fr'!D8:D86,"<>") -> 79 | C32: =COUNTIF('pampers-fr_fr'!D8:D86,"Active") -> 46 | D32: =COUNTIF('pampers-fr_fr'!D8:D86,"Inactive") -> 33 | E32: =IFERROR(D32/B32,0) -> 0.41772152 | F32: =SUM('pampers-fr_fr'!M8:M86) -> 30952 | G32: =SUMIF('pampers-fr_fr'!D8:D86,"Inactive",'pampers-fr_fr'!M8:M86) -> 6541 | H32: =IFERROR(G32/F32,0) -> 0.21132722 | I32: {=SUMPRODUCT(--('pampers-fr_fr'!D8:D86<>""),--(LEN(TRIM('pampers-fr_fr'!J8:J86))=0))} -> 10 | J32: {=SUMPRODUCT(--('pampers-fr_fr'!D8:D86<>""),--(LEN(TRIM('pampers-fr_fr'!F8:F86))=0))} -> 4 | K32: {=SUMPRODUCT(--('pampers-fr_fr'!D8:D86<>""),--(LEN(TRIM('pampers-fr_fr'!H8:H86))=0))} -> 10 | L32: =IF(G32>0,"Hidden reviews reduce social proof.","No hidden-review impact found.") -> Hidden reviews reduce social proof. | M32: =IF(G32>0,"Map reviewed IDs; then activate.","Maintain status governance.") -> Map reviewed IDs; then activate. | N32: =IF(G32>0,"CRUCIAL",IF(I32>0,"HIGH",IF(J32+K32>0,"MEDIUM","LOW"))) -> CRUCIAL
A33: Spain | B33: =COUNTIF(pgdodotspain!D8:D36,"<>") -> 29 | C33: =COUNTIF(pgdodotspain!D8:D36,"Active") -> 1 | D33: =COUNTIF(pgdodotspain!D8:D36,"Inactive") -> 28 | E33: =IFERROR(D33/B33,0) -> 0.96551724 | F33: =SUM(pgdodotspain!M8:M36) -> 5979 | G33: =SUMIF(pgdodotspain!D8:D36,"Inactive",pgdodotspain!M8:M36) -> 5977 | H33: =IFERROR(G33/F33,0) -> 0.9996655 | I33: {=SUMPRODUCT(--(pgdodotspain!D8:D36<>""),--(LEN(TRIM(pgdodotspain!J8:J36))=0))} -> 10 | J33: {=SUMPRODUCT(--(pgdodotspain!D8:D36<>""),--(LEN(TRIM(pgdodotspain!F8:F36))=0))} -> 9 | K33: {=SUMPRODUCT(--(pgdodotspain!D8:D36<>""),--(LEN(TRIM(pgdodotspain!H8:H36))=0))} -> 9 | L33: =IF(G33>0,"Hidden reviews reduce social proof.","No hidden-review impact found.") -> Hidden reviews reduce social proof. | M33: =IF(G33>0,"Map reviewed IDs; then activate.","Maintain status governance.") -> Map reviewed IDs; then activate. | N33: =IF(G33>0,"CRUCIAL",IF(I33>0,"HIGH",IF(J33+K33>0,"MEDIUM","LOW"))) -> CRUCIAL
A34: Japan | B34: =COUNTIF('pampers-ja_jp'!D8:D40,"<>") -> 33 | C34: =COUNTIF('pampers-ja_jp'!D8:D40,"Active") -> 0 | D34: =COUNTIF('pampers-ja_jp'!D8:D40,"Inactive") -> 33 | E34: =IFERROR(D34/B34,0) -> 1 | F34: =SUM('pampers-ja_jp'!M8:M40) -> 3105 | G34: =SUMIF('pampers-ja_jp'!D8:D40,"Inactive",'pampers-ja_jp'!M8:M40) -> 3105 | H34: =IFERROR(G34/F34,0) -> 1 | I34: {=SUMPRODUCT(--('pampers-ja_jp'!D8:D40<>""),--(LEN(TRIM('pampers-ja_jp'!J8:J40))=0))} -> 10 | J34: {=SUMPRODUCT(--('pampers-ja_jp'!D8:D40<>""),--(LEN(TRIM('pampers-ja_jp'!F8:F40))=0))} -> 2 | K34: {=SUMPRODUCT(--('pampers-ja_jp'!D8:D40<>""),--(LEN(TRIM('pampers-ja_jp'!H8:H40))=0))} -> 3 | L34: =IF(G34>0,"Hidden reviews reduce social proof.","No hidden-review impact found.") -> Hidden reviews reduce social proof. | M34: =IF(G34>0,"Map reviewed IDs; then activate.","Maintain status governance.") -> Map reviewed IDs; then activate. | N34: =IF(G34>0,"CRUCIAL",IF(I34>0,"HIGH",IF(J34+K34>0,"MEDIUM","LOW"))) -> CRUCIAL
A35: TOTAL | B35: =SUM(B28:B34) -> 368 | C35: =SUM(C28:C34) -> 93 | D35: =SUM(D28:D34) -> 275 | E35: =IFERROR(D35/B35,0) -> 0.74728261 | F35: =SUM(F28:F34) -> 239994 | G35: =SUM(G28:G34) -> 62301 | H35: =IFERROR(G35/F35,0) -> 0.25959399 | I35: =SUM(I28:I34) -> 85 | J35: =SUM(J28:J34) -> 67 | K35: =SUM(K28:K34) -> 78 | L35: ="Hidden reviews: "&TEXT(G35,"#,##0") -> Hidden reviews: 62,301 | M35: ="Prioritize "&TEXT(G35,"#,##0")&" hidden reviews." -> Prioritize 62,301 hidden reviews. | N35: =IF(G35>0,"CRUCIAL","LOW") -> CRUCIAL
A37: Immediate attention: prioritize instances with the largest hidden-review volume; North American instances are listed first. No Canada instance is present in this workbook.
A39: SECTION 3: ISSUES WITH BUSINESS IMPACT, RECOMMENDATIONS & HOW TO FIX
A40: Instance / Region | B40: # | C40: Issue Category | D40: Critical Field | E40: Volume Impacted | F40: Business Impact | G40: Recommended Action | H40: How to Fix | I40: Suggestion Impact
A41: United States (EN) | B41: 1 | C41: Inactive Products → Reviews Hidden/Tagged to Inactive Product | D41: Product Status | E41: 77 products / 34000 reviews | F41: Hidden reviews reduce social proof. | G41: Reactivate or migrate reviewed products. | H41: Map IDs to live PDPs; then activate. | I41: CRUCIAL
A42: United States (EN) | B42: 2 | C42: Product ID Issues | D42: Product ID | E42: Numeric 60; alphanumeric 62; blank 0 | F42: Mixed IDs hinder catalog matching. | G42: Adopt one canonical ID standard. | H42: Map legacy IDs; publish canonical IDs. | I42: HIGH
A43: United States (EN) | B43: 3 | C43: UPC Data Missing Issues | D43: UPC | E43: 36 products | F43: Missing codes can block syndication. | G43: Populate approved UPC values. | H43: Validate source codes; update column I. | I43: HIGH
A44: United States (EN) | B44: 4 | C44: Missing Crucial Fields | D44: Name/PDP/Description/Image/Brand | E44: 53 products | F44: Missing content weakens PDP quality. | G44: Complete required catalog fields. | H44: Backfill from approved product masters. | I44: MEDIUM
A45: United States (EN) | B45: 5 | C45: Brand Name Issues | D45: Brand | E45: 3 variations | F45: Brand variants fragment reporting. | G45: Use one approved brand label. | H45: Normalize case, spacing, and aliases. | I45: MEDIUM
...

Sheet pampers-fr_fr
A1: Bazaarvoice
A2: Pampers-FR_FR R&R Key Metrics
A3: Run Date: Aug 12, 2026 12:00 AM UTC
A4: Instance: pampers-fr_fr
A5: Date range: All Time
A6: Date field: Review Submission Date
A7: Brand ID | B7: Brand | C7: Product ID | D7: Product Status | E7: Product Name | F7: Description | G7: Product Page URL | H7: Image URL | I7: UPC | J7: EAN | K7: Product Family | L7: Product Family - Expand | M7: # Approved Reviews
A8: 7-FR | B8: Pampers FR | C8: 181156484-FR | D8: Inactive | E8: Lingettes Pampers Sensitive | F8: Pendant que vous nettoyez et prenez soin de la peau de votre bébé, vous pouvez en profiter pour créer un lien avec lui. Offrez à votre bébé une toilette rafraîchissante avec les nouvelles lingettes Pampers Sensitive, qui intègrent à présent la nouvelle Soft Grip Texture™ unique. Elles sont désormais 15 % plus épaisses avec un motif ultra-doux. Ces lingettes sont plus efficaces pour une toilette plus douce. Donc, la seule chose que votre bébé sent lorsque vous le changez, c'est votre amour. | G8: http://dev.pampers.fr/Lingettes-Pampers-Sensitive | H8: http://dev.pampers.fr/fr_FR/images/pc/hb/lsp/products/prod_image_main_wipes_sensitive.png | M8: 1
A9: 7-FR | B9: Pampers FR | C9: 181156482-FR | D9: Inactive | E9: Pampers Active Fit | F9: Pampers Active Fit sont nos couches les plus absorbantes et les mieux ajustées. Elles offrent à votre bébé jusqu'à 12 heures bien au sec et, grâce à leur système d'ajustement 3-Way Fit, s'adaptent parfaitement au niveau de la taille, des cuisses et de l'entrejambe. | G9: http://dev.pampers.fr/Pampers-Active-Fit | H9: http://dev.pampers.fr/fr_FR/images/pc/hb/lsp/products/prod_image_main_diaper_activefit.png | J9: 4015400598947, 4015400599180, 4015400599241, 4015400599272, 4015400599302, 4015400617693, 4015400617778, 4015400617792, 4015400618218, 4015400618232, 4015400618256, 4015400618270, 4015400618836, 4015400618898, 4015400618928, 4015400618959, 4015400622543, 4015400696315, 4015400696346, 4015400696377, 4015400696407, 4015400696438, 4015400696469, 4015400696506, 4015400696544, 4015400696582, 4015400696629, 4015400696667, 4015400697374, 4015400697459, 4015400697497, 4015400697572, 4015400697626, 4015400697664, 4015400697701, 4015400697763, 4015400697909, 4015400697947, 4015400699422 | M9: 11
A10: 7-FR | B10: Pampers FR | C10: 181148361-FR | D10: Inactive | E10: Lingettes Pampers Sensitive | F10: Chaque pli et chaque fossette ont besoin de votre amour. C'est pourquoi Les lingettes Pampers Sensitive sont imprégnées de la lotion Pure Care qui nettoie tout en douceur et rétablit le pH naturel de la peau. | G10: http://www.pampers.fr/lingettes-pour-bebes-pampers-sensitive | H10: http://www.pampers.fr/fr_FR/images/pc/hb/products/prod_img_wipes_sensitiveNor.jpg | M10: 4
A11: 7-FR | B11: Pampers FR | C11: 8-FR | D11: Inactive | E11: Lingettes Pampers Sans Parfum | F11: Les lingettes Pampers nettoient et rafraîchissent la peau de bébé. La toilette Pampers existe aussi sans parfum | G11: http://64.58.71.185/fr_FR/proddetail/baby-products/naturals/id/8 | H11: http://64.58.71.185/fr_FR/products/images/nt_gb_183_173_b.gif | M11: 1
A12: 7-FR | B12: Pampers FR | C12: 181156481-FR | D12: Inactive | E12: Pampers New Baby | F12: Notre meilleure protection pour la peau des nouveau-nés. Chaque petit miracle mérite la meilleure protection, c'est pourquoi nos nouvelles couches New Baby sont à présent dotées d'un indicateur d’urine coloré. Il devient bleu quand bébé fait pipi pour vous signaler qu'il faut changer sa couche. Elles sont dotées du système Double Absorption exclusif, spécialement conçu pour absorber les selles molles des nouveau-nés et les garder bien au sec. Et elles sont maintenant encore plus douces pour apporter à votre bébé un confort et une protection exceptionnels. En complément, utilisez les nouvelles lingettes Sensitive Maximum Care, nos lingettes les plus douces pour une toilette Pampers tout en douceur de la peau délicate de votre bébé. | G12: http://dev.pampers.fr/Pampers-New-Baby | H12: http://dev.pampers.fr/fr_FR/images/pc/hb/lsp/products/prod_image_main_diaper_newbaby.png | M12: 30
A13: 7-FR | B13: Pampers FR | C13: 1-FR | D13: Inactive | E13: Couches Pampers Micro | F13: A la sortie de la maternité, les couches Pampers Micro sont conçues pour le change des bébés de petit poids et des prématurés. Dotée de toute la protection Pampers, la couche Pampers Micro s’adapte à la morphologie de bébés de petit poids (de 1 kg à 2,5 kg) | G13: http://64.58.71.185/fr_FR/proddetail/baby-products/micro/id/1/sectionid/0 | H13: http://64.58.71.185/fr_FR/products/images/af_fr_183_173_b.gif | M13: 7
A14: 7-FR | B14: Pampers FR | C14: 181156483-FR | D14: Inactive | E14: Simply Dry | F14: Les couches Pampers Simply Dry sont une bonne solution pour les mamans qui veulent faire attention à leurs dépenses. Elles vous offrent l'absorption Pampers à un prix abordable, pour profiter pleinement des moments passés avec votre bébé sans vous ruiner. | G14: http://dev.pampers.fr/Simply-Dry | H14: http://dev.pampers.fr/fr_FR/images/pc/hb/lsp/products/prod_image_main_diaper_simplydry.png | J14: 4015400549710, 4015400549741, 4015400549802, 4015400549833, 4015400549864, 4015400549895, 4015400549925, 4015400686484, 4015400687030, 4015400687054, 4015400687078 | M14: 16
A15: PAMPERS | B15: Pampers | C15: 8006540704615 | D15: Active | E15: PAMPERS PP GEANT T3 X46 | F15: PAMPERS PP GEANT T3 X46 | G15: https://fd12-courses.leclercdrive.fr/magasin-077201-077201-Ferte-Bernard/fiche-produits-205935-Couches-Pampers-Premium.aspx | H15: https://fd12-courses.leclercdrive.fr/magasin-077201-077201-Ferte-Bernard/fiche-produits-205935-Couches-Pampers-Premium.aspx | J15: 8006540704615 | M15: 19
A16: PAMPERS | B16: Pampers | C16: 8700216263764 | D16: Active | E16: PAMPERS BABY DRY MAXI T6 X78 | F16: PAMPERS BABY DRY MAXI T6 X78 | G16: https://fd9-courses.leclercdrive.fr/magasin-010901-010901-Saint-Jean-du-Falga/fiche-produits-212904-Couches-Pampers-Baby-Dry.aspx | H16: https://fd9-photos.leclercdrive.fr/image.ashx?id=2696438&use=d&cat=p&typeid=i | J16: 8700216263764 | M16: 9
A17: PAMPERS | B17: Pampers | C17: PAMPERS_SENSITIVE_ZERO_PLASTIQUE_LINGETTES | D17: Inactive | E17: Pampers® Sensitive 0% Plastique | F17: Pampers® Sensitive 0% Plastique | G17: https://www.pampers.fr/couches-et-lingettes/pampers-sensitive-zero-plastique-lingettes | H17: https://images.ctfassets.net/g4icgs65at4c/5zaINWN2mqjmpFe4O5x1Nk/62ce5ee0531349ac2d409be41161ef71/200x200_pampersSensitive_wipes.png | J17: 8006540523056, 8006540523087, 8006540523124 | M17: 8
A18: PAMPERS | B18: Pampers | C18: 8006540715802 | D18: Active | E18: PAMPERS BABY DRY GEANT T5 X39 | F18: PAMPERS BABY DRY GEANT T5 X39 | G18: https://fd12-courses.leclercdrive.fr/magasin-077201-077201-Ferte-Bernard/fiche-produits-205853-Couches-Pampers-Baby-dry.aspx | H18: https://fd12-courses.leclercdrive.fr/magasin-077201-077201-Ferte-Bernard/fiche-produits-205853-Couches-Pampers-Baby-dry.aspx | J18: 8006540715802 | M18: 18
A19: PAMPERS | B19: Pampers | C19: PPP-FRFR | D19: Active | E19: Pampers® Premium Protection™ Pants | F19: Pampers® Premium Protection™ Pants | G19: https://www.pampers.fr/couches-et-lingettes/pampers-premium-protection-pants-couches-culottes | H19: https://images.ctfassets.net/g4icgs65at4c/6Epbbb9TInXvKI9IMVqyzP/2491c83c3023dffa8f649a586bb55030/2099_44_Pampers_FR_PPPants_PDPUpdate_FEB24-PPP-324x286.png | J19: 8001090184009, 8006540710074, 8006540710104, 8006540710135, 8006540710166, 8006540710197, 8006540710227, 8006540710357, 8006540710395, 8006540710418, 8006540710432, 8006540710456, 8006540710470, 8006540710494, 8006540710517, 8006540710531, 8006540759059, 8700216664332, 8700216679091, 8700216679107, 8700216679121, 8700216679176, 8700216679183, 8700216679268, 8700216679275, 8700216679312, 8700216679336, 8700216679381, 8700216679404, 8700216679466 | M19: 1160
A20: PAMPERS | B20: Pampers | C20: 8006540704646 | D20: Active | E20: PAMPERS PP GEANT T4 X39 | F20: PAMPERS PP GEANT T4 X39 | G20: https://fd12-courses.leclercdrive.fr/magasin-077201-077201-Ferte-Bernard/fiche-produits-202858-Couches-Pampers-Premium.aspx | H20: https://fd12-courses.leclercdrive.fr/magasin-077201-077201-Ferte-Bernard/fiche-produits-202858-Couches-Pampers-Premium.aspx | J20: 8006540704646 | M20: 16
A21: PAMPERS | B21: Pampers | C21: 8700216290951 | D21: Active | E21: PAMPERS BD PANTS MAXI T5 X82 | F21: PAMPERS BD PANTS MAXI T5 X82 | G21: https://fd12-courses.leclercdrive.fr/magasin-077201-077201-Ferte-Bernard/fiche-produits-223871-Couches-culottes-Pampers-Baby.aspx | H21: https://fd12-courses.leclercdrive.fr/magasin-077201-077201-Ferte-Bernard/fiche-produits-223871-Couches-culottes-Pampers-Baby.aspx | J21: 8700216290951 | M21: 10
A22: PAMPERS | B22: Pampers | C22: 8700216251327 | D22: Active | E22: PAMPERS HARMONIE GEANT T4 X36 | F22: PAMPERS HARMONIE GEANT T4 X36 | G22: https://fd12-courses.leclercdrive.fr/magasin-077201-077201-Ferte-Bernard/fiche-produits-223903-Couches-Pampers-Harmonie.aspx | H22: https://fd12-courses.leclercdrive.fr/magasin-077201-077201-Ferte-Bernard/fiche-produits-223903-Couches-Pampers-Harmonie.aspx | J22: 8700216251327 | M22: 10
A23: PAMPERS | B23: Pampers | C23: active-fit-pants-FR | D23: Inactive | E23: COUCHES-CULOTTES Pampers Active Fit Pants | F23: COUCHES-CULOTTES Pampers Active Fit Pants | G23: https://www.pampers.fr/produits/pampers-premium-active-fit-pants-couches-culottes | H23: http://azcdn.multibrand.pgsitecore.com/fr-FR/-/media/Pampers/Pampers-FR/Images/Products/Product-Oasis/Closed-Module/Active-Fit-Pants/ClosedModule-ActiveFitsPants-FR.png?v=3-201803140534 | M23: 433
A24: PAMPERS | B24: Pampers | C24: 8006540715734 | D24: Active | E24: PAMPERS BABY DRY GEANT T4 X45 | F24: PAMPERS BABY DRY GEANT T4 X45 | G24: https://fd12-courses.leclercdrive.fr/magasin-077201-077201-Ferte-Bernard/fiche-produits-205941-Couches-Pampers-Baby-dry.aspx | H24: https://fd12-courses.leclercdrive.fr/magasin-077201-077201-Ferte-Bernard/fiche-produits-205941-Couches-Pampers-Baby-dry.aspx | J24: 8006540715734 | M24: 14
A25: PAMPERS | B25: Pampers | C25: 8006540780350 | D25: Active | E25: PAMPERS PP NB GEANT T1 X42 | F25: PAMPERS PP NB GEANT T1 X42 | G25: https://fd12-courses.leclercdrive.fr/magasin-077201-077201-Ferte-Bernard/fiche-produits-205945-Couches-Pampers-Premium.aspx | H25: https://fd12-courses.leclercdrive.fr/magasin-077201-077201-Ferte-Bernard/fiche-produits-205945-Couches-Pampers-Premium.aspx | J25: 8006540780350 | M25: 11
A26: PAMPERS | B26: Pampers | C26: 8700216263795 | D26: Active | E26: PAMPERS BABY DRY MAXI T5 X90 | F26: PAMPERS BABY DRY MAXI T5 X90 | G26: https://fd12-courses.leclercdrive.fr/magasin-077201-077201-Ferte-Bernard/fiche-produits-223862-Couches-Pampers-Baby-Dry-Maxi.aspx | H26: https://fd12-photos.leclercdrive.fr/image.ashx?id=2685479&use=d&cat=p&typeid=i | J26: 8700216263795 | M26: 13
A27: PAMPERS | B27: Pampers | C27: PAMPERS_BABY_DRY_NIGHT_PANTS | D27: Active | E27: Pampers® Baby-Dry™ Night Pants | F27: Pampers® Baby-Dry™ Night Pants | G27: https://www.pampers.fr/couches-et-lingettes/pampers-baby-dry-night-pants | H27: https://images.ctfassets.net/g4icgs65at4c/6Qudm6RtfxEqaVFcqLQR5r/8ea9327f35f8bfb5c333ff00565d73f7/2099_48_Pampers_FR_BDYNP_PDPUpdate_FEB24-BDNP-324x286.png | J27: 8006540234792, 8006540234853, 8006540710739, 8006540710975, 8006540711309, 8006540711569, 8006540711828, 8006540711910, 8700216669696, 8700216669764, 8700216669795, 8700216669887 | M27: 130
A28: PAMPERS | B28: Pampers | C28: 11-FR | D28: Inactive | E28: Kandoo | F28: Kandoo | G28: https://www.pampers.fr/produit-normal/kandoo | H28: http://cdn.multibrand.pgsitecore.com/fr-FR/-/media/Pampers/Pampers-FR/Images/Products/Primary/pampers-kandoo-refill-toilet-wipes-melon-50-630x330.png?v=1-201505060814 | J28: 4015400192381, 4015400192787, 4015400192930 | M28: 20
A29: PAMPERS | B29: Pampers | C29: 8006540715697 | D29: Active | E29: PAMPERS BABY DRY GEANT T3 X52 | F29: PAMPERS BABY DRY GEANT T3 X52 | G29: https://fd12-courses.leclercdrive.fr/magasin-077201-077201-Ferte-Bernard/fiche-produits-205942-Couches-Pampers-Baby-dry.aspx | H29: https://fd12-courses.leclercdrive.fr/magasin-077201-077201-Ferte-Bernard/fiche-produits-205942-Couches-Pampers-Baby-dry.aspx | J29: 8006540715697 | M29: 18
A30: PAMPERS | B30: Pampers | C30: 6-FR | D30: Active | E30: Pampers® Sensitive™ | F30: Pampers® Sensitive™ | G30: https://www.pampers.fr/couches-et-lingettes/pampers-sensitive-lingettes | H30: https://images.ctfassets.net/g4icgs65at4c/1Jt1ydaFV2AP8pN9M47fy5/6ffaf5a9cc7f7ca1e12509229a5a864f/2099_63_Pampers_FR_Sensitive_Wipes_PDP_APR24-wipes-sensitive-324x286.png | J30: 8001841041391, 8001841041483, 8001841062556, 8001841062624, 8001841063188 | M30: 538
A31: PAMPERS | B31: Pampers | C31: 7-FR | D31: Active | E31: Pampers® Fresh Clean | F31: Pampers® Fresh Clean | G31: https://www.pampers.fr/couches-et-lingettes/pampers-fresh-clean-lingettes | H31: https://images.ctfassets.net/g4icgs65at4c/1ihhKZiaU9XtyqblumvJZx/b452707c9897b62f37349b9895d79541/2099_66_Pampers_FR_Fresh_Clean_Wipes_PDP_APR24-freshclean-324x286.png | J31: 4015400622567, 8001841041360, 8001841077598, 8001841077864, 8001841077949, 8001841078441, 8001841078496 | M31: 146
A32: PAMPERS | B32: Pampers | C32: NBPP-FRFR | D32: Inactive | E32: COUCHES Pampers Premium Protection | F32: COUCHES Pampers Premium Protection | G32: https://www.pampers.fr/produits/pampers-premium-protection-new-baby-couches | H32: https://res.cloudinary.com/pmprs/image/upload/c_scale,f_auto,q_60/v20191203225559/pampersc1/fr-fr/-/media/pampers/pampers-fr/images/products/product-oasis/closed-module/premium-protection-nb/closedmodule-premiumprotectionnb-fr.png?v=4-201904191351 | J32: 4015400557425, 4015400599425, 4015400599517, 4015400599548, 4015400599685, 4015400639015, 4015400701569, 4015400835646, 4015400835776, 4015400835851, 4015400835974, 4015400836025, 4015400849087, 4015400849155, 8001841057842, 8001841057866, 8718969860550 | M32: 532
A33: PAMPERS | B33: Pampers | C33: PAMPERS_HARMONIE_HYBRIDE | D33: Inactive | E33: Couches Pampers® Harmonie Hybrid | F33: Couches Pampers® Harmonie Hybrid | G33: https://www.pampers.fr/couches-et-lingettes/pampers-harmonie-hybrid-old | H33: https://images.ctfassets.net/g4icgs65at4c/zMpKbvNe5sfLotMzhivSQ/f8fa23163c381b2e7119cbabbf666497/200x200_pampersHybrid_probeerkit.png | J33: 8006540284254, 8006540284407, 8006540297933, 8006540297995, 8006540298022, 8006540354094, 8006540354155 | M33: 46
A34: PAMPERS | B34: Pampers | C34: 8700216207263 | D34: Active | E34: PAMPERS PP MAXI T4 X86 | F34: PAMPERS PP MAXI T4 X86 | G34: https://fd12-courses.leclercdrive.fr/magasin-077201-077201-Ferte-Bernard/fiche-produits-223899-Couches-Pampers-Premium.aspx | H34: https://fd12-photos.leclercdrive.fr/image.ashx?id=2737827&use=d&cat=p&typeid=i | J34: 8700216207263 | M34: 12
A35: PAMPERS | B35: Pampers | C35: 8700216207645 | D35: Active | E35: PAMPERS PP NB PAQUET T1 X24 | F35: PAMPERS PP NB PAQUET T1 X24 | G35: https://fd12-courses.leclercdrive.fr/magasin-077201-077201-Ferte-Bernard/fiche-produits-206094-Coucjes-Pampers-Premium.aspx | H35: https://fd12-courses.leclercdrive.fr/magasin-077201-077201-Ferte-Bernard/fiche-produits-206094-Coucjes-Pampers-Premium.aspx | J35: 8700216207645 | M35: 4
... A74: PAMPERS | B74: Pampers | C74: 181156501-FR | D74: Inactive | E74: LINGETTES Pampers New Baby Sensitive | F74: LINGETTES Pampers New Baby Sensitive | G74: https://www.pampers.fr/produits/pampers-new-baby-sensitive-lingettes | H74: http://azcdn.multibrand.pgsitecore.com/fr-FR/-/media/Pampers/Pampers-FR/Images/Products/Product-Oasis/Closed-Module/Wipes-NB-Sensitive/Closedmodule-Wipes-NB-Sensitive_FR.png?v=2-201709221355 | J74: 4015400623496, 4015400623663 | M74: 190
A75: PAMPERS_FR | B75: Pampers | C75: 5-FR | D75: Inactive | E75: Pampers Baby Dry | F75: Pampers Baby Dry | G75: http://www.pampers.fr/produit-star/pampers-baby-dry | J75: 4015400689218, 4015400689331, 4015400689416, 4015400689614, 4015400689652, 4015400696278, 4015400696872, 4015400705130, 4015400833260, 4015400833307, 4015400833338, 4015400833369, 4015400833390, 4015400833420, 4015400833444, 4015400833505, 4015400833550, 4015400833581, 4015400833628, 4015400833659, 4015400833765, 4015400833796, 4015400833826, 4015400833857, 4015400833871, 4015400833918, 4015400833956, 4015400833987, 4015400834021, 4015400834052, 4015400834083, 4015400834113, 4015400834144, 4015400834168, 4015400834205, 4015400834243, 4015400834274, 4015400834311, 4015400834335, 4015400834366, 4015400834397, 4015400834410, 4015400834458, 4015400834489, 4015400834748, 4015400834762, 4015400844006, 4015400844044, 4015400844082, 4015400844129, 4015400844150 | M75: 15
A76: PAMPERS_FR | B76: Pampers | C76: 2-FR | D76: Inactive | E76: Pampers New Baby | F76: Pampers New Baby | G76: http://www.pampers.fr/produit-star/pampers-new-baby | J76: 4015400599456, 4015400639015, 4015400835646, 4015400835776, 4015400835851, 4015400835936, 4015400836025, 4015400849087, 4015400849155, 4015400849193 | M76: 962
A77: PAMPERS_FR | B77: Pampers | C77: 75 | D77: Inactive | E77: Pampers Baby-Dry | F77: Pampers Baby-Dry | G77: http://www.pampers.fr/produit-star/pampers-baby-dry | J77: 4015400542902, 4015400542940, 4015400543480, 4015400601876, 4015400602149, 4015400602170, 4015400602248, 4015400602309, 4015400602330, 4015400602361, 4015400625896, 4015400626428, 4015400646242, 4015400646341, 4015400646839, 4015400659921, 4015400659952, 4015400659976, 4015400689218, 4015400689263, 4015400689331, 4015400689416, 4015400689454, 4015400689492, 4015400689539, 4015400689614, 4015400689652, 4015400694458, 4015400694489, 4015400694502, 4015400694526, 4015400695578, 4015400695592, 4015400695615, 4015400695639, 4015400695653, 4015400695677, 4015400695691, 4015400695714, 4015400695769, 4015400695783, 4015400695806, 4015400695837, 4015400696155, 4015400696186, 4015400696216, 4015400696247, 4015400696278, 4015400696872, 4015400696933, 4015400705130, 4015400705161, 4015400729624, 4015400729655, 4015400729679, 4015400730804, 4015400730835 | M77: 1101
A78: PAMPERS_FR | B78: Pampers | C78: 4-FR | D78: Inactive | E78: Pampers Easy Up | F78: Pampers Easy Up | J78: 4015400293637, 4015400535690, 4015400535737, 4015400535805, 4015400535843, 4015400535881, 4015400535942, 4015400535973, 4015400536000, 4015400536086, 4015400536123, 4015400536178, 4015400536208, 4015400536239, 4015400536253, 4015400536277, 4015400536291 | M78: 17
...

Sheet pampers-en_gb
A1: Bazaarvoice
A2: Pampers-EN_GB R&R Key Metrics
A3: Run Date: Aug 12, 2026 12:00 AM UTC
A4: Instance: pampers-en_gb
A5: Date range: All Time
A6: Date field: Review Submission Date
A7: Brand ID | B7: Brand | C7: Product ID | D7: Product Status | E7: Product Name | F7: Description | G7: Product Page URL | H7: Image URL | I7: UPC | J7: EAN | K7: Product Family | L7: Product Family - Expand | M7: # Approved Reviews
A8: PAMPERS | B8: Pampers | C8: 171156441-GB | D8: Active | E8: Pampers® Sensitive™ | F8: Pampers® Sensitive™ | G8: https://www.pampers.co.uk/products/pampers-sensitive | H8: https://images.ctfassets.net/3shtzlb7cz90/48cDtEQSjqSWO1EBQEyMCN/cf1f7b947709171b52bbb7284a7761c4/2146_37_Pampers_UK_Sensitive_Wipes_PDP_MAR24_Cross_sell_1.png | J8: 8001841062792, 8001841041391, 8001841062754, 8006540836194, 8001841062303, 8001841062976, 8001841041421, 8001841041483, 8001841062440, 8001841063188, 8001841062624, 8001841062334, 8001841276151 | M8: 178
A9: PAMPERS | B9: Pampers | C9: 171156443-GB | D9: Inactive | E9: WIPES Pampers Complete Clean Scented | F9: WIPES Pampers Complete Clean Scented | G9: https://www.pampers.co.uk/products/pampers-complete-clean-scented-wipes | H9: https://azcdn.multibrand.pgsitecore.com/en-GB/-/media/Pampers/Pampers-UK/Images/Products/Product-Oasis/Complete-Clean-scented/Complete_Clean_scented_Closed_box_Packshot.png?v=1-201706161100 | J9: 4015400622734, 4015400622840 | M9: 14
A10: PAMPERS | B10: Pampers | C10: PAMPERS_HARMONIE_PANTS | D10: Active | E10: Pampers® Harmonie | F10: Pampers® Harmonie | G10: https://www.pampers.co.uk/products/pampers-harmonie-pants | H10: https://images.ctfassets.net/3shtzlb7cz90/7LSCfrCqciY5v0jaJUyZoZ/55e5d519618be4931290175042750382/Packshot_img_1_324x286.png | J10: 8006540460610, 8006540460672, 8006540460733, 8006540867952, 8006540867990, 8700216235648, 8700216235655, 8700216235693 | M10: 1
A11: PAMPERS | B11: Pampers | C11: PAMPERS_PREMIUM_PROTECTION | D11: Inactive | E11: NAPPIES Pampers Premium Protection | F11: NAPPIES Pampers Premium Protection | G11: https://www.pampers.co.uk/products/pampers-premium-protection-nappies | H11: https://res.cloudinary.com/pmprs/image/upload/c_fill,f_auto/v20191128114838/pampersc1/en-gb/-/media/pampers/pampers-uk/images/products/product-oasis/updated-packshots/premium-protection_150x150.png?v=2-201911281148 | J11: 4015400599456, 4015400835332, 4015400835370, 4015400835448, 4015400835509, 4015400835936, 4015400849193, 4015400849247, 4015400849285, 4015400855293, 4015400855323, 4015400855354, 8001090287861, 8001090287946, 8001090287984, 8001090288011, 8001090299642, 8001090608840, 8001090609380, 8001090609557, 8001090609632, 8001090610058, 8001841201276, 8001841201306 | M11: 435
A12: PAMPERS | B12: Pampers | C12: Harmonie_99percent_Water | D12: Inactive | E12: Pampers® 99% Water Wipe | F12: Pampers® 99% Water Wipe | G12: https://www.pampers.co.uk/products/pampers-aqua-baby-wipes-plastic-free | H12: https://images.ctfassets.net/2ql69mthp94m/D7gwYdv5XHA8GZr9E6zsz/dcf25c494ae1329d60d358e82a567b48/3881_22_Pampers_UK_Wipes_Product_Pages_JAN26_packs_Pure_skin_400x350.png?fm=avif&w=500 | J12: 8006530116558, 8006530116305, 8006530116152, 8006530116374, 8006530116459, 8006530116206 | M12: 56
A13: PAMPERS | B13: Pampers | C13: PAMPERS_NINJAMAS_PYJAMA_PANTS | D13: Active | E13: PAMPERS® NINJAMAS | F13: PAMPERS® NINJAMAS | G13: https://www.pampers.co.uk/products/pampers-ninjamas-pyjama-pants | H13: https://images.ctfassets.net/3shtzlb7cz90/23EKtrYTU7TcncYQWiiBLH/27d1ff67260edc8af63756aea50390c2/2146_10_Pampers_UK_Ninjamas_PDP_JUL23_324x286.png | J13: 8006540630464, 8006540630488, 8006540630518, 8006540630549, 8006540630563, 8006540630587, 8006540630617, 8006540630648, 8700216189583, 8700216189613, 8700216189644, 8700216189651 | M13: 672
A14: PAMPERS | B14: Pampers | C14: PAMPERS_BABY_DRY_TAPE | D14: Active | E14: Pampers® Baby-Dry™ | F14: Pampers® Baby-Dry™ | G14: https://www.pampers.co.uk/products/pampers-baby-dry | H14: https://images.ctfassets.net/3shtzlb7cz90/3FfQbEdwQ4BPcKJAomggsJ/34e9abe6105ad7c099c5d3fcec4809c9/Packshot_img_324x286.png | J14: 4015400542940, 4015400566663, 4015400566700, 4015400566748, 4015400566786, 4015400566823, 4015400566892, 4015400601876, 4015400602149, 4015400689263, 4015400689331, 4015400689454, 4015400689539, 4015400689614, 4015400695677, 4015400695691, 4015400695714, 4015400833444, 4015400833871, 4015400834274, 4015400834410, 4015400834489, 4015400834991, 4015400835035, 4015400835097, 8001090156839, 8001090197672, 8001090197740, 8001090197887, 8001090197917, 8001090268679, 8001090298300, 8001090368553, 8001090368577, 8001090383648, 8001090406507, 8001090672216, 8001090672247, 8001090672285, 8001090672414, 8001090672520, 8001841793085, 8001841793108, 8001841793122, 8001841793146, 8006540697801, 8006540697825, 8006540697849, 8006540697863, 8006540827215, 8006540827277, 8006540827307, 8006540827338, 8006540861691, 8006540861714, 8006540861738, 8006540861752, 8700216036191, 8700216036214, 8700216036245, 8700216036276, 8700216036306, 8700216036344, 8700216036375, 8700216036412, 8700216036436, 8700216458733 | M14: 2208
A15: PAMPERS | B15: Pampers | C15: Sensitive-0-Plastic | D15: Active | E15: Pampers® Sensitive™ 0% Plastic | F15: Pampers® Sensitive™ 0% Plastic | G15: https://www.pampers.co.uk/products/pampers-sensitive-0-plastic | H15: https://images.ctfassets.net/3shtzlb7cz90/blYUTMacSopZ379S4BFYj/836326cdd5a87669e5c80f4c0cb9a87b/2146_47_Pampers_UK_Sensitive_Zero_Plastic_PDP_APR24-Packshot.png | J15: 8006540523056, 8006540523087, 8006540523124 | M15: 3
A16: PAMPERS | B16: Pampers | C16: pampers-kids-hygiene-on-the-go-wipes | D16: Inactive | E16: Pampers® Kids Hygiene on-the-go Wipes | F16: Pampers® Kids Hygiene on-the-go Wipes | G16: https://www.pampers.co.uk/products/pampers-hygiene-wipes | H16: https://images.ctfassets.net/3shtzlb7cz90/01E7PQ50LFBOCyXJ50n8ek/5c09f67196d372683aaacf44869a3c03/KidsHygiene.png | J16: 8006540222089, 8006540222140, 8006540222324 | M16: 158
A17: PAMPERS | B17: Pampers | C17: 171153601-GB | D17: Inactive | E17: New Baby Sensitive | F17: New Baby Sensitive | G17: https://www.pampers.co.uk/star-product/new-baby-sensitive | H17: http://cdn.multibrand.pgsitecore.com/en-GB/-/media/Pampers/Pampers-Master/Images/Products/UK/Regular-Products/Secondary/Pampers-New-Baby-Sensitive-Size-1-Carry-Pack-23-Nappies_4015400611356_630x330.png?v=1-201503020743 | J17: 4015400611356, 4015400635109, 4015400635178, 4015400635215 | M17: 19
A18: PAMPERS | B18: Pampers | C18: PAMPERS_COCONUT_PURE_WIPES | D18: Active | E18: Pampers® Harmonie Protect & Care 0% Plastic | F18: Pampers® Harmonie Protect & Care 0% Plastic | G18: https://www.pampers.co.uk/products/pampers-harmonie-protect-care-plastic-free | H18: https://images.ctfassets.net/3shtzlb7cz90/2wwOup1wCJY9dHF8GJxCty/27a7b0f66349a56ac185851f3995a25e/Image_Background_Remover__1_.png | M18: 31
A19: PAMPERS | B19: Pampers | C19: PAMPERS_NEW_BABY | D19: Active | E19: Pampers® Premium Protection New Baby Wipe | F19: Pampers® Premium Protection New Baby Wipe | G19: https://www.pampers.co.uk/products/pampers-premium-protection-new-baby-wipes | H19: https://images.ctfassets.net/2ql69mthp94m/6mFfqz6dzyUmDfFzmG1Gaz/4bd22dce4ff9bf8b71bd82d14ac59e9f/3881_22_Pampers_UK_Wipes_Product_Pages_JAN26_packs_New_baby_400x350.png?fm=avif&w=500 | J19: 8700216038546, 8001841859088, 8001841794884, 8001841794822, 8006530145985, 8006530145992, 8700216038294, 8001841794761, 8001841794853, 8001841859187, 8006530145947, 8001841794792, 8001841859163, 8006530145893, 8001841859156, 8001841859101, 8006530146067, 8700216038317, 8001841794730, 4015400639015, 8006530145954, 8700216038638 | M19: 1673
A20: PAMPERS | B20: Pampers | C20: 171074149-GB | D20: Inactive | E20: Pampers Kandoo toilet wipes for children | F20: Pampers Kandoo toilet wipes for children | G20: https://www.pampers.co.uk/product/pampers-kandoo-toilet-wipes-for-children | H20: http://cdn.multibrand.pgsitecore.com/en-GB/-/media/Pampers/Pampers-Master/Images/Products/UK/Regular-Products/Secondary/Pampers-Kandoo-Refill-Toilet-Wipes-Melon-50-per-pack-_4015400192381_630x330.png?v=1-201503020743 | M20: 2
A21: PAMPERS | B21: Pampers | C21: Harmonie_Aqua_Baby_Wipes_Plastic_Free | D21: Active | E21: Pampers Harmonie Aqua 0% plastic | F21: Pampers Harmonie Aqua 0% plastic | G21: https://www.pampers.co.uk/products/pampers-aqua-baby-wipes-plastic-free | H21: https://images.ctfassets.net/3shtzlb7cz90/3E0sVXNzipHQLx1yaucyca/cb8d935edecb670c410b59b83cb96836/packshot_img_324x286.png | J21: 8006540458525, 8006540458563, 8006540510247, 8006540556139, 8006540811245, 8006540811276, 8700216722476, 8700216722520 | M21: 443
A22: PAMPERS | B22: Pampers | C22: 171155881-GB | D22: Inactive | E22: Sleep and Play | F22: Sleep and Play | G22: https://www.pampers.co.uk/product/simply-dry | H22: http://cdn.multibrand.pgsitecore.com/en-GB/-/media/Pampers/Pampers-Master/Images/Products/UK/Regular-Products/Secondary/Pampers-Simply-Dry-Size-3-Carry-Pack-30-Nappies_4015400549567_630x330.png?v=1-201608190828 | J22: 4015400549567, 4015400549659, 4015400549680, 4015400549710, 4015400549741, 4015400549772, 4015400549802, 4015400549833, 4015400549864, 4015400549895, 4015400549925, 4015400613879, 4015400613909, 4015400686484, 4015400687030, 4015400687054, 4015400687078, 4015400687092 | M22: 9
A23: PAMPERS | B23: Pampers | C23: PAMPERS_HARMONIE_NEW_BABY_WIPES | D23: Active | E23: Pampers® Harmonie New Baby | F23: Pampers® Harmonie New Baby | G23: https://www.pampers.co.uk/products/pampers-harmonie-new-baby-wipes | H23: https://images.ctfassets.net/3shtzlb7cz90/68D4S68smhj72R6MjTXUoe/44fa600c0aae53a75d5d2fe2897f8d8d/product_page_benefit_2A_mobile_165x165.png | J23: 8006540815762, 8006540815885, 8700216026253 | M23: 80
A24: PAMPERS | B24: Pampers | C24: 171074138-GB | D24: Inactive | E24: Pampers – Underjams (Girls) | F24: Pampers – Underjams (Girls) | G24: https://www.pampers.co.uk/product/pampers-underjams-girls | H24: http://cdn.multibrand.pgsitecore.com/en-GB/-/media/Pampers/Pampers-Master/Images/Products/UK/Regular-Products/Secondary/Pampers-Underjams-Girls-S_630x330.png?v=1-201503020743 | J24: 4015400345053, 4015400345305 | M24: 0
A25: PAMPERS | B25: Pampers | C25: pampers-new-baby-sensitive-wipes | D25: Inactive | E25: Pampers® New Baby Wipes | F25: Pampers® New Baby Wipes | G25: https://www.pampers.co.uk/products/pampers-new-baby-sensitive-wipes | H25: https://images.ctfassets.net/3shtzlb7cz90/3D2HSapq6t3PQZObnuWe4q/a4524a887260d25b84af374298e423d3/NBS__1_.png | J25: 4015400623496, 4015400623663, 4015400670414 | M25: 39
A26: PAMPERS | B26: Pampers | C26: PAMPERS_BABY_DRY_NIGHT_PANTS | D26: Inactive | E26: Pampers® Baby-Dry™ Night Nappy Pants | F26: Pampers® Baby-Dry™ Night Nappy Pants | G26: https://www.pampers.co.uk/products/pampers-baby-dry-night-pants-old | H26: https://images.ctfassets.net/3shtzlb7cz90/6Zw6K7EI7SK5Gf9cbyZQ4a/b05d5e0a0b5872fe44585a9d97ed8de5/2146_4_Pampers_UK_Night_Pants_PDP_JUL23_200x200.png | J26: 8006540234792, 8006540234822, 8006540234853, 8006540291900, 8006540291924, 8006540291948, 8006540416242, 8006540416273, 8006540416303, 8700216039369, 8700216039390, 8700216039406 | M26: 110
A27: PAMPERS | B27: Pampers | C27: 20150226-1-GB | D27: Inactive | E27: WIPES Pampers Sensitive Protect | F27: WIPES Pampers Sensitive Protect | G27: https://www.pampers.co.uk/products/pampers-sensitive-protect-wipes | H27: https://azcdn.multibrand.pgsitecore.com/en-GB/-/media/Pampers/Pampers-UK/Images/Products/Product-Oasis/Pampers-Sensitive-Protect-Wipes/SENSITIVE_PROTECT_IMG_PACK.png?v=1-201706190510 | J27: 4015400621966, 4015400622079, 4015400622222, 4015400622284 | M27: 140
A28: PAMPERS | B28: Pampers | C28: PAMPERS_ACTIVE_FIT_NAPPY_PANTS | D28: Active | E28: Pampers® Premium Protection | F28: Pampers® Premium Protection | G28: https://www.pampers.co.uk/products/pampers-premium-protection-nappy-pants | H28: https://images.ctfassets.net/3shtzlb7cz90/6KS4yvelCPzANmVo1w0Z8Q/12c9811b6f698ca0f8c649af80f749a9/3197_22_Pampers_UK_Product_Pages_Updates_JAN25_PPP_Packshots_324x286.png | J28: 8001090184009, 8001090184047, 8001090184092, 8001841770611, 8001841770642, 8001841770673, 8001841770703, 8001841770734, 8001841770765, 8006540132272, 8006540132296, 8006540132319, 8700216038928, 8700216038935, 8700216038942, 8700216039031, 8700216039062, 8700216039086, 8700216123303, 8700216123341, 8700216705387 | M28: 1221
A29: PAMPERS | B29: Pampers | C29: 171074137-GB | D29: Inactive | E29: Pampers – Underjams (boys) | F29: Pampers – Underjams (boys) | G29: https://www.pampers.co.uk/product/pampers-underjams-boys | H29: http://cdn.multibrand.pgsitecore.com/en-GB/-/media/Pampers/Pampers-Master/Images/Products/UK/Regular-Products/Secondary/Pampers-Underjams-Boys-S_630x330.png?v=1-201503020743 | J29: 4015400345022, 4015400345275 | M29: 1
A30: PAMPERS | B30: Pampers | C30: 171156442-GB | D30: Inactive | E30: WIPES Pampers Complete Clean Unscented | F30: WIPES Pampers Complete Clean Unscented | G30: https://www.pampers.co.uk/products/pampers-complete-clean-unscented-wipes | H30: https://azcdn.multibrand.pgsitecore.com/en-GB/-/media/Pampers/Pampers-UK/Images/Products/Product-Oasis/Complete-Clean-Unscented/Complete-clean-unscented-closed-box-packshot.png?v=1-201706161059 | J30: 4015400622413, 4015400622482 | M30: 5
A31: PAMPERS | B31: Pampers | C31: PAMPERS_BABY_DRY_PANTS | D31: Active | E31: Pampers® Baby-Dry™ | F31: Pampers® Baby-Dry™ | G31: https://www.pampers.co.uk/products/pampers-baby-dry-pants | H31: https://images.ctfassets.net/3shtzlb7cz90/2GxAU0eNZc4rux9YdC8VAb/f5216ff65b6353e0c57b7b8a20e6f2f7/2146_44_Pampers_UK_Baby_Dry_Pants_PDP_APR24-BDYP-324x286.png | J31: 4015400744887, 4015400744917, 4015400744948, 4015400749608, 4015400749646, 4015400841043, 4015400841524, 4015400841593, 8001090706485, 8001090706577, 8001090706645, 8001090706713, 8001090706850, 8001090706898, 8001090706935, 8001090924759, 8001090967961, 8001090968029, 8001090968081, 8001841072562, 8001841072722, 8001841072760, 8001841072999, 8001841073149, 8001841103365, 8001841122854, 8001841122885, 8001841129075, 8001841129099, 8001841159430, 8001841159461, 8001841159492, 8001841159522, 8001841159553, 8001841159584, 8001841159614, 8001841159652, 8001841159676, 8001841159706, 8001841793337, 8001841793368, 8001841793399, 8006540002452, 8006540002483, 8006540002513, 8006540337417, 8006540450451, 8006540450482, 8006540450512, 8006540463383, 8006540710876, 8006540711248, 8006540711767, 8006540825297, 8006540825327, 8700216039116, 8700216039161, 8700216039192, 8700216039222, 8700216039246, 8700216039260, 8700216039284, 8700216039314, 8700216039338, 8700216039345, 8700216455787, 8700216455794, 8700216455817, 8700216705226, 8700216705257, 8700216705264, 8700216705318 | M31: 1543
A32: PAMPERS | B32: Pampers | C32: PAMPERS_FRESH_CLEAN_PLASTIC_FREE | D32: Inactive | E32: Pampers® Fresh Clean 0% Plastic Wipe | F32: Pampers® Fresh Clean 0% Plastic Wipe | G32: https://www.pampers.co.uk/products/pampers-fresh-clean-plastic-free-baby-wipes | H32: https://images.ctfassets.net/2ql69mthp94m/DQNSPkrMy14kCeTQl0CTf/261aa691b6d04f318708f440ebdef687/3881_22_Pampers_UK_Wipes_Product_Pages_JAN26_packs_Fresh_clean_V2_400x350.png?fm=avif&w=500 | J32: 8006530098366, 8006530098403, 8006530098441 | M32: 64
A33: PAMPERS | B33: Pampers | C33: PAMPERS_SENSITIVE_PLASTIC_FREE | D33: Inactive | E33: Pampers® Sensitive™ 0% Plastic | F33: Pampers® Sensitive™ 0% Plastic | G33: https://www.pampers.co.uk/products/pampers-sensitive-0-plastic | H33: https://images.ctfassets.net/3shtzlb7cz90/blYUTMacSopZ379S4BFYj/836326cdd5a87669e5c80f4c0cb9a87b/2146_47_Pampers_UK_Sensitive_Zero_Plastic_PDP_APR24-Packshot.png | J33: 8006540523056, 8006540523100, 8006540523124, 8700216783491 | M33: 36
A34: PAMPERS_UK | B34: Pampers | C34: 171074136-GB | D34: Inactive | E34: Pampers Easy Up Pants | F34: Pampers Easy Up Pants | J34: 4015400535942, 4015400535973, 4015400536000, 4015400536031, 4015400536062, 4015400536239, 4015400536253, 4015400605232, 4015400605256 | M34: 0
A35: PAMPERS_UK | B35: Pampers | C35: Aqua_Pure_Wipes | D35: Inactive | E35: Pampers® Aqua Pure™ | F35: Pampers® Aqua Pure™ | G35: https://www.pampers.co.uk/products/pampers-aqua-pure-wipes | H35: https://images.ctfassets.net/3shtzlb7cz90/7K9ioh7Kn65yUDoGPRQfOm/6af2ad8a93078f6e4ffb80277bb5b7a4/Pampers-Aqua-Pure-280x195.png | J35: 8001090603296, 8001090603326, 8001090603388, 8001090603470, 8001090603500, 8001090603562, 8001090603609, 8001090603623, 8001090603661 | M35: 433
A36: PAMPERS_UK | B36: Pampers | C36: 20150226-GB | D36: Inactive | E36: Pampers Sensitive Baby Wipes Perfume Free | F36: Pampers Sensitive Baby Wipes Perfume Free | J36: 4015400621966, 4015400622079, 4015400622116, 4015400622284, 4015400630791, 4015400670414 | M36: 0
A37: pampers-en_gb | B37: PAMPERS | C37: Pure_Protection_Nappies | D37: Active | E37: Pampers® Harmonie | F37: Pampers® Harmonie | G37: https://www.pampers.co.uk/products/pampers-harmonie-nappies | H37: https://images.ctfassets.net/3shtzlb7cz90/75smodrmOcXB8T6YTP4Env/6dff3465f7ce8ba7d33fd95e2f3e6d96/2146_59_Pampers_UK_Harmonie_Pants_Packshot_Update_JUN24_harmonie__1_.png | J37: 8006540867921, 8006540156599, 8700216251716, 8006540156476, 8001841023120, 8006540156353, 8001841115979, 8001090834904, 8700216251792, 8700216251259, 8700216251235, 8700216251754, 8001090834843, 8006540156414, 8006540156636, 8001090834720, 8001841115917, 8006540156674, 8700216251679, 8001090834966, 8006540156551, 8001090834782, 8001841116037, 8001090971982, 8006540867808, 8006540867891, 8006540156384, 8001090972026, 8700216251686, 8006540156155, 8006540156445 | M37: 680
A38: pampers-en_gb | B38: PAMPERS | C38: PAMPER_ACTIVE_FIT | D38: Active | E38: Pampers® Active Fit | F38: Pampers® Active Fit | G38: https://www.pampers.co.uk/products/pampers-active-fit-nappies | H38: https://images.ctfassets.net/3shtzlb7cz90/4f996eb73e5afe297516099754e8dd5a27fffbae1ebb29bd5321bc0afb1d984c/5680a8575dcb1402507d6cf4e43e4d73/PROJ024724-P_G-Pampers-Standard-Packshot-4-324x286-v0.01.png | J38: 8001841808499, 8001841808550, 8001841808611, 8001841808680, 8001841808741, 8001841808772, 8001841808833, 8001841808901, 8001841809038, 8001841809052, 8001841809076, 8700216038379, 8700216038393, 8700216038416, 8700216038560, 8700216038591, 8700216038607 | M38: 2724
A39: pampers-en_gb | B39: PAMPERS | C39: PAMPERS_SPLASHERS | D39: Active | E39: Pampers® Splashers Baby Shark™ | F39: Pampers® Splashers Baby Shark™ | G39: https://www.pampers.co.uk/products/pampers-splashers | H39: https://images.ctfassets.net/3shtzlb7cz90/1YjQuCWgqXJdxahUSr90Rj/08af74edfad5a09b25152a98ff937f25/1026_63_Pampers_FR_Splashers_UpdatePDP_MAR23_324x286.png | J39: 8001090698346, 8001090698384, 8001090728951 | M39: 24
A40: pampers-en_gb | B40: PAMPERS | C40: PAMPERS_FRESH_CLEAN | D40: Active | E40: Pampers® Fresh Clean | F40: Pampers® Fresh Clean | G40: https://www.pampers.co.uk/products/pampers-fresh-clean | H40: https://images.ctfassets.net/3shtzlb7cz90/6RDoT3S9z87DOK2OK6O73U/9dd86e111337904dd346100567ab0149/2146_38_Pampers_UK_Fresh_Clean_Wipes_PDP_MAR24_benefit2A_mobile_165x165.png | J40: 8001841077789, 8001841077598, 8001841078052, 8001841276007, 8001841078137, 8001841078441, 8001841077949, 8001841078496, 8001841041360 | M40: 82
...

Sheet pampers-en_us
A1: Bazaarvoice
A2: Pampers-EN_US R&R Key Metrics
A3: Run Date: Aug 12, 2026 12:00 AM UTC
A4: Instance: pampers
A5: Date range: All Time
A6: Date field: Review Submission Date
A7: Brand ID | B7: Brand | C7: Product ID | D7: Product Status | E7: Product Name | F7: Description | G7: Product Page URL | H7: Image URL | I7: UPC | J7: EAN | K7: Product Family | L7: Product Family - Expand | M7: # Approved Reviews
A8: 16n8p5scqgr7lpve64m2tvx8c | B8: Pampers | C8: 037000275046 | D8: Inactive | E8: Pampers Pure Hybrid Starter Kit | F8: Pampers Pure Protection Hybrid Cloth Diaper Starter Kit - 3 Reusable Covers + 25 Disposable Inserts | H8: https://target.scene7.com/is/image/Target/GUEST_9740c937-0d2b-42fa-8462-c6595948f112?fmt=webp&wid=1400&qlt=80 | I8: 037000275046 | M8: 116
A9: 16n8p5scqgr7lpve64m2tvx8c | B9: Pampers | C9: 10900806 | D9: Inactive | E9: Easy Ups Trainers for Girls | F9: <li>Helps potty training make sense during the day and protects against leaks at night</li> <li>Training pants designed for toddlers or preschoolers ready for potty training (18+ months old)</li> <li>The Feel 'n Learn&reg; Liner helps your little girl feel when she's wet, so she can learn to stay dry</li> | G9: http://www.pampers.com/potty-training-girls-easy-ups | H9: https://www.pampers.com/en_US/images/pc/hb/products/prod_img_pampers_easy_ups_girls_NA.jpg | I9: 037000066989, 037000067634, 037000067726 | M9: 22
A10: 16n8p5scqgr7lpve64m2tvx8c | B10: Pampers | C10: 900815 | D10: Inactive | E10: Pampers® SoftCare Unscented Wipes | F10: <li>SoftCare unscented baby wipes are made with pure water</li> <li>Lotion with natural aloe & vitamin E</li> <li>SoftCare baby wipes have thousands of soft cleansing buds</li> <li>Cleans gently like a baby’s washcloth</li> <li>Hypoallergenic</li> | G10: http://www.pampers.com/softcare-unscented-wipes | H10: https://www.pampers.com/en_US/images/pc/hb/products/prod_img_wipes_softcare_unscented_NA.jpg | I10: 037000061618 | M10: 3
A11: 16n8p5scqgr7lpve64m2tvx8c | B11: Pampers | C11: 10900805 | D11: Inactive | E11: Easy Ups Trainers for Boys | F11: <li>Helps potty training make sense during the day and protects against leaks at night</li> <li>Training pants designed for toddlers or preschoolers ready for potty training (18+ months old)</li> <li>The Feel 'n Learn&reg; Liner helps your little boy feel when he's wet, so he can learn to stay dry</li> | G11: http://www.pampers.com/potty-training-boys-easy-ups | H11: https://www.pampers.com/en_US/images/pc/hb/products/prod_img_pampers_easy_ups_boys_NA.jpg | I11: 037000067559, 037000067702, 037000067795 | M11: 37
A12: 16n8p5scqgr7lpve64m2tvx8c | B12: Pampers | C12: 900804 | D12: Inactive | E12: Baby Dry Diapers | F12: <li>Extra flexible tabs expand and contract with your baby</li> <li>UltraAbsorb Core&trade; Outstanding overnight absorbance</li> <li>Comfortable contoured fit</li> | G12: http://www.pampers.com/baby-diaper-baby-dry | H12: https://www.pampers.com/en_US/images/pc/hb/products/prdt_116x128_babydry.gif | I12: 037000066859, 037000067450, 037000067511, 037000312901, 037000452157, 037000601487 | M12: 0
A13: 16n8p5scqgr7lpve64m2tvx8c | B13: Pampers | C13: 900826 | D13: Inactive | E13: Pampers® Swaddlers diapers | F13: <li>Color-changing Wetness Indicator (size NB, 1 and 2)</li> <li>The #1 choice of hospitals (based on sales data)</li> <li>Quilted blanket-like softness wraps babies in comfort and security</li> <li>Soft stretchy sides and overlapping fasteners give infants a flexible fit</li> <li>Umbilical cord notch (size NB only)</li> | G13: http://www.pampers.com/new-baby-diapers-swaddlers | H13: https://www.pampers.com/en_US/images/pc/hb/products/prod_img_diapers_swaddlers_NA.jpg | I13: 037000285199, 037000285229, 037000285397, 037000285502, 037000348955, 037000397984 | M13: 1
A14: 16n8p5scqgr7lpve64m2tvx8c | B14: Pampers | C14: 761042387 | D14: Inactive | E14: Kandoo Flushable Toilet Wipes | F14: <li>Cleans up to 30% better than toilet paper</li> <li>Perfect fit for little hands- about the size of two pieces of toilet paper</li> <li>Available in a variety of scents, including Smellin' Melon, Magic Melon, Funny Berry, and Sensitive</li> | G14: http://www.pampers.com/flushable-wipes-kandoo | H14: https://www.pampers.com/en_US/images/pc/hb/lsp/products/prod_image_wipes_kandoo.png | I14: 037000041757, 037000048770, 037000159186, 037000449904 | M14: 807
A15: 16n8p5scqgr7lpve64m2tvx8c | B15: Pampers | C15: 900807 | D15: Inactive | E15: Pampers® Sensitive Baby Wipes | F15: <li>Pampers Sensitive baby wipes have PureCare lotion which conditions baby’s skin</li> <li>Pampers Sensitive wipes are dermatologist tested</li> <li>Hypoallergenic and Perfume Free</li> <li>#1 baby wipe of hospitals (based on sales data)</li> <li>Clinically proven mild baby wipes for your baby’s skin</li> | G15: http://www.pampers.com/pampers-sensitive-baby-wipes | H15: https://www.pampers.com/en_US/images/pc/hb/products/prod_img_wipes_sensitive_NA.jpg | I15: 037000436904 | M15: 1
A16: 16n8p5scqgr7lpve64m2tvx8c | B16: Pampers | C16: Pampers_Clean_&_Calm | D16: Active | E16: Pampers® Clean & Calm™ | F16: Pampers® Clean & Calm™ Cotton Blossom Scent | G16: https://www.pampers.com/en-us/products/pampers-clean-and-calm-wipes | H16: https://sampling2-product-images-prod.s3.amazonaws.com/bvsampling/Pampers-Pampers_Clean_and_Calm.png?t=1741790457602 | I16: 030772204313, 030772204320, 030772204344, 030772204368 | M16: 1124
A17: 16n8p5scqgr7lpve64m2tvx8c | B17: Pampers | C17: 900803 | D17: Inactive | G17: http://www.pampers.com/pampers-cruisers | H17: https://www.pampers.com/en_US/images/pc/hb/products/prod_img_pampers_cruisers_NA.jpg | I17: 037000063964, 037000064008, 037000064039, 037000064060, 037000119104 | M17: 141
A18: 16n8p5scqgr7lpve64m2tvx8c | B18: Pampers | C18: 900821 | D18: Inactive | E18: Bibsters | G18: http://stage.pampers.com/en_US/proddetail/baby-products/baby-bibs-bibsters/id/900821 | H18: https://stage.pampers.com/en_US/products/new_layout/images/Nprdt_bibster.gif | I18: 037000401803 | M18: 5
A19: 16n8p5scqgr7lpve64m2tvx8c | B19: Pampers | C19: 10900826 | D19: Inactive | E19: Pampers® Swaddlers diapers | F19: <li>Color-changing Wetness Indicator (size NB, 1 and 2)</li> <li>The #1 choice of hospitals (based on sales data)</li> <li>Quilted blanket-like softness wraps babies in comfort and security</li> <li>Soft stretchy sides and overlapping fasteners give infants a flexible fit</li> <li>Umbilical cord notch (size NB only)</li> | G19: http://www.pampers.com/new-baby-diapers-swaddlers | H19: https://www.pampers.com/en_US/images/pc/hb/products/prod_img_diapers_swaddlers_NA.jpg | I19: 037000285199, 037000285229, 037000285397, 037000285502, 037000348955, 037000397984 | M19: 276
A20: 16n8p5scqgr7lpve64m2tvx8c | B20: Pampers | C20: 80335332 | D20: Inactive | E20: Expressions Wipes | F20: Baby Wipe | H20: https://sampling-photos-prod.s3.amazonaws.com/photos/4d1c690d414dfd615901088bb360aba5_image_%2823%29.jpg | I20: 037000579939 | M20: 49
A21: 16n8p5scqgr7lpve64m2tvx8c | B21: Pampers | C21: 10900802 | D21: Inactive | E21: Pampers® Swaddlers Sensitive diapers | F21: <li>Gentle and hypoallergenic</li> <li>Made with a touch of aloe</li> <li>Ultra breathability</li> <li>Color-changing Wetness Indicator (size NB, 1, 2)</li> <li>Umbilical cord notch (size NB only)</li> | G21: http://www.pampers.com/swaddlers-sensitive-diapers | H21: https://www.pampers.com/en_US/images/pc/hb/products/prod_img_diapers_swaddlers_sensitive_NA.jpg | I21: 037000172311, 037000172406, 037000172468 | M21: 87
